[2022-10-10 16:23:24,041] {taskinstance.py:1159} INFO - Dependencies all met for <TaskInstance: user_processing.process_user __airflow_temporary_run_2022-10-10T16:23:15.380166+00:00__ [queued]>
[2022-10-10 16:23:24,417] {taskinstance.py:1159} INFO - Dependencies all met for <TaskInstance: user_processing.process_user __airflow_temporary_run_2022-10-10T16:23:15.380166+00:00__ [queued]>
[2022-10-10 16:23:24,495] {taskinstance.py:1356} INFO - 
--------------------------------------------------------------------------------
[2022-10-10 16:23:24,496] {taskinstance.py:1357} INFO - Starting attempt 1 of 1
[2022-10-10 16:23:24,498] {taskinstance.py:1358} INFO - 
--------------------------------------------------------------------------------
[2022-10-10 16:23:24,872] {taskinstance.py:1377} INFO - Executing <Task(PythonOperator): process_user> on 2022-01-01 00:00:00+00:00
[2022-10-10 16:23:24,907] {standard_task_runner.py:52} INFO - Started process 6441 to run task
[2022-10-10 16:23:25,130] {standard_task_runner.py:79} INFO - Running: ['***', 'tasks', 'run', 'user_processing', 'process_user', '__***_temporary_run_2022-10-10T16:23:15.380166+00:00__', '--job-id', '17', '--raw', '--subdir', 'DAGS_FOLDER/user_processing.py', '--cfg-path', '/tmp/tmpbunqjesd', '--error-file', '/tmp/tmp5spoee9u']
[2022-10-10 16:23:25,180] {standard_task_runner.py:80} INFO - Job 17: Subtask process_user
[2022-10-10 16:23:34,152] {task_command.py:369} INFO - Running <TaskInstance: user_processing.process_user __airflow_temporary_run_2022-10-10T16:23:15.380166+00:00__ [running]> on host 09023156d4e0
[2022-10-10 16:23:37,206] {taskinstance.py:1571} INFO - Exporting the following env vars:
AIRFLOW_CTX_DAG_OWNER=***
AIRFLOW_CTX_DAG_ID=user_processing
AIRFLOW_CTX_TASK_ID=process_user
AIRFLOW_CTX_EXECUTION_DATE=2022-01-01T00:00:00+00:00
AIRFLOW_CTX_TRY_NUMBER=1
AIRFLOW_CTX_DAG_RUN_ID=__***_temporary_run_2022-10-10T16:23:15.380166+00:00__
[2022-10-10 16:23:37,515] {logging_mixin.py:115} INFO - None
[2022-10-10 16:23:37,539] {taskinstance.py:1889} ERROR - Task failed with exception
Traceback (most recent call last):
  File "/home/airflow/.local/lib/python3.7/site-packages/airflow/operators/python.py", line 171, in execute
    return_value = self.execute_callable()
  File "/home/airflow/.local/lib/python3.7/site-packages/airflow/operators/python.py", line 189, in execute_callable
    return self.python_callable(*self.op_args, **self.op_kwargs)
  File "/opt/airflow/dags/user_processing.py", line 14, in _process_user
    user = user['results'][0]
TypeError: 'NoneType' object is not subscriptable
[2022-10-10 16:23:37,764] {taskinstance.py:1400} INFO - Marking task as FAILED. dag_id=user_processing, task_id=process_user, execution_date=20220101T000000, start_date=20221010T162324, end_date=20221010T162337
[2022-10-10 16:23:38,027] {standard_task_runner.py:97} ERROR - Failed to execute job 17 for task process_user ('NoneType' object is not subscriptable; 6441)
[2022-10-10 16:23:38,298] {local_task_job.py:156} INFO - Task exited with return code 1
[2022-10-10 16:23:38,936] {local_task_job.py:273} INFO - 0 downstream tasks scheduled from follow-on schedule check
